<?xml version='1.0' encoding='utf-8'?>
<robot name="folding-mechanism">
  <link name="back_left_axle">
    <inertial>
      <origin xyz="0.04 -0.0492115 0.04" rpy="0 0 0" />
      <mass value="0.0246615" />
      <inertia ixx="3.08269e-07" ixy="4.88276e-37" ixz="-1.323e-38" iyy="3.44233e-06" iyz="2.15845e-24" izz="3.44233e-06" />
    </inertial>
    <visual>
      <origin xyz="-2.77556e-17 -0.098675 0.0612924" rpy="-0.0259869 -0 -6.71907e-32" />
      <geometry>
        <mesh filename="package://assets/back_left_axle.stl" />
      </geometry>
      <material name="red_material">
        <color rgba="0.8 0.2 0.2 1.0" />
      </material>
    </visual>
    <collision>
      <origin xyz="-2.77556e-17 -0.098675 0.0612924" rpy="-0.0259869 -0 -6.71907e-32" />
      <geometry>
        <mesh filename="package://assets/back_left_axle.stl" />
      </geometry>
    </collision>
  </link>
  <link name="back_link">
    <inertial>
      <origin xyz="0.116673 -0.116673 0.04" rpy="0 0 0" />
      <mass value="0.372616" />
      <inertia ixx="0.00208024" ixy="0.00152199" ixz="-3.254e-41" iyy="0.00208024" iyz="1.15197e-40" izz="0.00306294" />
    </inertial>
    <visual>
      <origin xyz="-0.05 -0.02 0.04" rpy="1.5708 1.5708 0" />
      <geometry>
        <mesh filename="package://assets/back_link.stl" />
      </geometry>
      <material name="back_link_material">
        <color rgba="0.231373 0.380392 0.705882 1.0" />
      </material>
    </visual>
    <collision>
      <origin xyz="-0.05 -0.02 0.04" rpy="1.5708 1.5708 0" />
      <geometry>
        <mesh filename="package://assets/back_link.stl" />
      </geometry>
    </collision>
  </link>
  <joint name="Revolute 6" type="revolute">
    <origin xyz="0.04 -0.0492115 0.04" rpy="-1.5708 0.101767 1.5708" />
    <parent link="back_left_axle" />
    <child link="back_link" />
    <axis xyz="0 0 1" />
    <limit effort="10" velocity="10" lower="-3.141592653589793" upper="3.141592653589793" />
  </joint>
  <link name="back_left_base_fork">
    <inertial>
      <origin xyz="-6.93889e-18 0.0108384 0.02" rpy="0 0 0" />
      <mass value="0.0418822" />
      <inertia ixx="1.00185e-05" ixy="0" ixz="0" iyy="9.25611e-06" iyz="0" izz="2.42204e-06" />
    </inertial>
    <visual>
      <origin xyz="-0.05 -0.02 0.06" rpy="1.5708 1.5708 0" />
      <geometry>
        <mesh filename="package://assets/back_left_base_fork.stl" />
      </geometry>
      <material name="back_left_base_fork_material">
        <color rgba="0.647059 0.647059 0.647059 1.0" />
      </material>
    </visual>
    <collision>
      <origin xyz="-0.05 -0.02 0.06" rpy="1.5708 1.5708 0" />
      <geometry>
        <mesh filename="package://assets/back_left_base_fork.stl" />
      </geometry>
    </collision>
  </link>
  <link name="base">
    <inertial>
      <origin xyz="0 0 0" rpy="0 0 0" />
      <mass value="1e-09" />
      <inertia ixx="1e-09" ixy="0" ixz="0" iyy="1e-09" iyz="0" izz="1e-09" />
    </inertial>
    <visual>
      <origin xyz="-0.04 -0.0507885 0.0375" rpy="3.22659e-16 7.0169e-17 1.00369e-16" />
      <geometry>
        <mesh filename="package://assets/base.stl" />
      </geometry>
      <material name="base_material">
        <color rgba="0.972549 0.529412 0.00392157 1.0" />
      </material>
    </visual>
    <collision>
      <origin xyz="-0.04 -0.0507885 0.0375" rpy="3.22659e-16 7.0169e-17 1.00369e-16" />
      <geometry>
        <mesh filename="package://assets/base.stl" />
      </geometry>
    </collision>
    <visual>
      <origin xyz="-0.04 0.0492115 -0.0225" rpy="-3.46945e-18 -4.49024e-49 -1.29422e-31" />
      <geometry>
        <mesh filename="package://assets/ground.stl" />
      </geometry>
      <material name="ground_material">
        <color rgba="0.768627 0.886275 0.952941 1.0" />
      </material>
    </visual>
    <collision>
      <origin xyz="-0.04 0.0492115 -0.0225" rpy="-3.46945e-18 -4.49024e-49 -1.29422e-31" />
      <geometry>
        <mesh filename="package://assets/ground.stl" />
      </geometry>
    </collision>
  </link>
  <link name="front_joint_fork">
    <inertial>
      <origin xyz="1.36486e-17 -4.9964e-19 -0.00666159" rpy="0 0 0" />
      <mass value="0.0418822" />
      <inertia ixx="2.42204e-06" ixy="0" ixz="0" iyy="1.00185e-05" iyz="0" izz="9.25611e-06" />
    </inertial>
    <visual>
      <origin xyz="-1.97641e-17 -2.08167e-19 -0.0175" rpy="3.14159 -0 0" />
      <geometry>
        <mesh filename="package://assets/front_joint_fork.stl" />
      </geometry>
      <material name="front_joint_fork_material">
        <color rgba="0.647059 0.647059 0.647059 1.0" />
      </material>
    </visual>
    <collision>
      <origin xyz="-1.97641e-17 -2.08167e-19 -0.0175" rpy="3.14159 -0 0" />
      <geometry>
        <mesh filename="package://assets/front_joint_fork.stl" />
      </geometry>
    </collision>
  </link>
  <link name="front_axle_joint">
    <inertial>
      <origin xyz="3.9655e-20 7.34251e-18 -0.02" rpy="0 0 0" />
      <mass value="0.0246615" />
      <inertia ixx="3.44233e-06" ixy="-3.31019e-35" ixz="-1.0302e-36" iyy="3.44233e-06" iyz="-1.45256e-51" izz="3.08269e-07" />
    </inertial>
    <visual>
      <origin xyz="2.08167e-19 6.93889e-18 -0.02" rpy="-1.5708 -1.5708 0" />
      <geometry>
        <mesh filename="package://assets/front_axle_joint.stl" />
      </geometry>
      <material name="front_axle_joint_material">
        <color rgba="0.615686 0.811765 0.929412 1.0" />
      </material>
    </visual>
    <collision>
      <origin xyz="2.08167e-19 6.93889e-18 -0.02" rpy="-1.5708 -1.5708 0" />
      <geometry>
        <mesh filename="package://assets/front_axle_joint.stl" />
      </geometry>
    </collision>
  </link>
  <link name="front_bottom_link">
    <inertial>
      <origin xyz="0.128563 0.103424 -1.73355e-16" rpy="0 0 0" />
      <mass value="0.161703" />
      <inertia ixx="0.000602729" ixy="-0.000742114" ixz="1.24307e-18" iyy="0.000928217" iyz="9.9918e-19" izz="0.00152857" />
    </inertial>
    <visual>
      <origin xyz="-1.16573e-15 3.63598e-15 -5.5852e-33" rpy="-1.67874 -1.5708 0" />
      <geometry>
        <mesh filename="package://assets/front_bottom_link.stl" />
      </geometry>
      <material name="front_bottom_link_material">
        <color rgba="0.231373 0.380392 0.705882 1.0" />
      </material>
    </visual>
    <collision>
      <origin xyz="-1.16573e-15 3.63598e-15 -5.5852e-33" rpy="-1.67874 -1.5708 0" />
      <geometry>
        <mesh filename="package://assets/front_bottom_link.stl" />
      </geometry>
    </collision>
  </link>
  <link name="middle_plate_front_axle">
    <inertial>
      <origin xyz="-1.61916e-18 0 -3.51292e-32" rpy="0 0 0" />
      <mass value="0.0678191" />
      <inertia ixx="6.88082e-05" ixy="9.54905e-22" ixz="-1.67187e-37" iyy="6.88082e-05" iyz="1.27219e-36" izz="8.47739e-07" />
    </inertial>
    <visual>
      <origin xyz="-0.233345 0.233345 -3.08149e-32" rpy="1.5708 1.5708 0" />
      <geometry>
        <mesh filename="package://assets/middle_plate_front_axle.stl" />
      </geometry>
      <material name="middle_plate_front_axle_material">
        <color rgba="0.972549 0.529412 0.00392157 1.0" />
      </material>
    </visual>
    <collision>
      <origin xyz="-0.233345 0.233345 -3.08149e-32" rpy="1.5708 1.5708 0" />
      <geometry>
        <mesh filename="package://assets/middle_plate_front_axle.stl" />
      </geometry>
    </collision>
  </link>
  <link name="middle_plate">
    <inertial>
      <origin xyz="0.0190173 -0.00531094 1.03041e-07" rpy="0 0 0" />
      <mass value="0.0911859" />
      <inertia ixx="9.20613e-05" ixy="9.13149e-06" ixz="1.15638e-10" iyy="0.000119162" iyz="-1.47904e-10" izz="3.64426e-05" />
    </inertial>
    <visual>
      <origin xyz="-0.212801 -0.252222 2.79786e-16" rpy="-1.48623 -1.5708 0" />
      <geometry>
        <mesh filename="package://assets/middle_plate.stl" />
      </geometry>
      <material name="middle_plate_material">
        <color rgba="0.917647 0.917647 0.917647 1.0" />
      </material>
    </visual>
    <collision>
      <origin xyz="-0.212801 -0.252222 2.79786e-16" rpy="-1.48623 -1.5708 0" />
      <geometry>
        <mesh filename="package://assets/middle_plate.stl" />
      </geometry>
    </collision>
  </link>
  <joint name="Cylindrical 7" type="revolute">
    <origin xyz="6.93889e-18 0 -2.46519e-32" rpy="-3.14159 -0 6.93889e-18" />
    <parent link="middle_plate_front_axle" />
    <child link="middle_plate" />
    <axis xyz="0 0 1" />
    <limit effort="10" velocity="10" lower="-3.141592653589793" upper="3.141592653589793" />
  </joint>
  <link name="top_left_link">
    <inertial>
      <origin xyz="-0.121181 0.0701076 -0.005" rpy="0 0 0" />
      <mass value="0.1376" />
      <inertia ixx="0.000239853" ixy="0.000406158" ixz="-9.0957e-19" iyy="0.000706923" iyz="5.25018e-19" izz="0.000944753" />
    </inertial>
    <visual>
      <origin xyz="-0.0575922 -0.324936 -0.055" rpy="-0.960818 -1.5708 0" />
      <geometry>
        <mesh filename="package://assets/top_left_link.stl" />
      </geometry>
      <material name="top_left_link_material">
        <color rgba="0.498039 0.498039 0.498039 1.0" />
      </material>
    </visual>
    <collision>
      <origin xyz="-0.0575922 -0.324936 -0.055" rpy="-0.960818 -1.5708 0" />
      <geometry>
        <mesh filename="package://assets/top_left_link.stl" />
      </geometry>
    </collision>
  </link>
  <joint name="Cylindrical 8" type="revolute">
    <origin xyz="1.38778e-17 0 -0.055" rpy="-3.14159 -0 6.93889e-18" />
    <parent link="middle_plate_front_axle" />
    <child link="top_left_link" />
    <axis xyz="0 0 1" />
    <limit effort="10" velocity="10" lower="-3.141592653589793" upper="3.141592653589793" />
  </joint>
  <link name="top_right_link">
    <inertial>
      <origin xyz="-0.0591666 -0.126883 0.005" rpy="0 0 0" />
      <mass value="0.1376" />
      <inertia ixx="0.000774541" ixy="-0.0003589" ixz="-9.31598e-35" iyy="0.000172235" iyz="0" izz="0.000944753" />
    </inertial>
    <visual>
      <origin xyz="-0.233345 0.233345 -0.045" rpy="1.5708 1.5708 0" />
      <geometry>
        <mesh filename="package://assets/top_right_link.stl" />
      </geometry>
      <material name="top_right_link_material">
        <color rgba="0.498039 0.498039 0.498039 1.0" />
      </material>
    </visual>
    <collision>
      <origin xyz="-0.233345 0.233345 -0.045" rpy="1.5708 1.5708 0" />
      <geometry>
        <mesh filename="package://assets/top_right_link.stl" />
      </geometry>
    </collision>
  </link>
  <link name="top_front_axle">
    <inertial>
      <origin xyz="1.11022e-16 -2.77556e-16 0.045" rpy="0 0 0" />
      <mass value="0.0678191" />
      <inertia ixx="6.88082e-05" ixy="2.23172e-18" ixz="5.47989e-20" iyy="6.88082e-05" iyz="-5.85179e-20" izz="8.47739e-07" />
    </inertial>
    <visual>
      <origin xyz="-0.427161 -0.260843 0.045" rpy="-2.36152 -1.5708 0" />
      <geometry>
        <mesh filename="package://assets/top_front_axle.stl" />
      </geometry>
      <material name="top_front_axle_material">
        <color rgba="0.231373 0.380392 0.705882 1.0" />
      </material>
    </visual>
    <collision>
      <origin xyz="-0.427161 -0.260843 0.045" rpy="-2.36152 -1.5708 0" />
      <geometry>
        <mesh filename="package://assets/top_front_axle.stl" />
      </geometry>
    </collision>
  </link>
  <link name="top_plate">
    <inertial>
      <origin xyz="0.000544372 -0.0204688 2.11833e-06" rpy="0 0 0" />
      <mass value="0.226762" />
      <inertia ixx="0.000204651" ixy="5.26894e-05" ixz="-2.13403e-08" iyy="0.000293005" iyz="6.97086e-09" izz="0.000161051" />
    </inertial>
    <visual>
      <origin xyz="0.0878865 0.492728 -2.44697e-16" rpy="1.97917 1.5708 0" />
      <geometry>
        <mesh filename="package://assets/top_plate.stl" />
      </geometry>
      <material name="top_plate_material">
        <color rgba="0.917647 0.917647 0.917647 1.0" />
      </material>
    </visual>
    <collision>
      <origin xyz="0.0878865 0.492728 -2.44697e-16" rpy="1.97917 1.5708 0" />
      <geometry>
        <mesh filename="package://assets/top_plate.stl" />
      </geometry>
    </collision>
  </link>
  <link name="top_rear_axle">
    <inertial>
      <origin xyz="-2.77556e-17 0 5.85111e-19" rpy="0 0 0" />
      <mass value="0.0110977" />
      <inertia ixx="3.68998e-07" ixy="1.02417e-23" ixz="8.24156e-39" iyy="3.68998e-07" iyz="2.66311e-23" izz="1.38721e-07" />
    </inertial>
    <visual>
      <origin xyz="-0.165012 -0.492611 -9.16641e-17" rpy="-1.5708 -1.5708 0" />
      <geometry>
        <mesh filename="package://assets/top_rear_axle.stl" />
      </geometry>
      <material name="top_rear_axle_material">
        <color rgba="0.768627 0.886275 0.952941 1.0" />
      </material>
    </visual>
    <collision>
      <origin xyz="-0.165012 -0.492611 -9.16641e-17" rpy="-1.5708 -1.5708 0" />
      <geometry>
        <mesh filename="package://assets/top_rear_axle.stl" />
      </geometry>
    </collision>
  </link>
  <link name="top_fork">
    <inertial>
      <origin xyz="1.04994e-09 -0.0137145 3.70982e-09" rpy="0 0 0" />
      <mass value="0.0424455" />
      <inertia ixx="6.53825e-06" ixy="1.89826e-15" ixz="5.46249e-13" iyy="4.6188e-06" iyz="1.73345e-13" izz="3.65373e-06" />
    </inertial>
    <visual>
      <origin xyz="-0.165012 -0.492611 -5.69696e-17" rpy="-1.5708 -1.5708 0" />
      <geometry>
        <mesh filename="package://assets/top_fork.stl" />
      </geometry>
      <material name="top_fork_material">
        <color rgba="0.647059 0.647059 0.647059 1.0" />
      </material>
    </visual>
    <collision>
      <origin xyz="-0.165012 -0.492611 -5.69696e-17" rpy="-1.5708 -1.5708 0" />
      <geometry>
        <mesh filename="package://assets/top_fork.stl" />
      </geometry>
    </collision>
  </link>
  <link name="top_rear_axle_2">
    <inertial>
      <origin xyz="-6.19936e-17 0 1.40427e-18" rpy="0 0 0" />
      <mass value="0.0184961" />
      <inertia ixx="1.50281e-06" ixy="-4.17114e-23" ixz="1.85236e-38" iyy="1.50281e-06" iyz="1.87907e-38" izz="2.31202e-07" />
    </inertial>
    <visual>
      <origin xyz="-0.165012 -0.467111 -4.16334e-17" rpy="-1.5708 -1.5708 0" />
      <geometry>
        <mesh filename="package://assets/top_rear_axle__2.stl" />
      </geometry>
      <material name="top_rear_axle_2_material">
        <color rgba="0.615686 0.811765 0.929412 1.0" />
      </material>
    </visual>
    <collision>
      <origin xyz="-0.165012 -0.467111 -4.16334e-17" rpy="-1.5708 -1.5708 0" />
      <geometry>
        <mesh filename="package://assets/top_rear_axle__2.stl" />
      </geometry>
    </collision>
  </link>
  <link name="top_back_link">
    <inertial>
      <origin xyz="0.0591666 0.126883 -3.38957e-19" rpy="0 0 0" />
      <mass value="0.1376" />
      <inertia ixx="0.000774541" ixy="-0.0003589" ixz="2.21189e-36" iyy="0.000172235" iyz="-6.88397e-36" izz="0.000944753" />
    </inertial>
    <visual>
      <origin xyz="-0.165012 0.467111 4.16334e-17" rpy="1.5708 1.5708 0" />
      <geometry>
        <mesh filename="package://assets/top_back_link.stl" />
      </geometry>
      <material name="top_back_link_material">
        <color rgba="0.980392 0.713725 0.00392157 1.0" />
      </material>
    </visual>
    <collision>
      <origin xyz="-0.165012 0.467111 4.16334e-17" rpy="1.5708 1.5708 0" />
      <geometry>
        <mesh filename="package://assets/top_back_link.stl" />
      </geometry>
    </collision>
  </link>
  <link name="middle_plate_rear_axle">
    <inertial>
      <origin xyz="1.38778e-17 0 4.01219e-18" rpy="0 0 0" />
      <mass value="0.0647364" />
      <inertia ixx="5.98812e-05" ixy="-5.84388e-20" ixz="6.44154e-21" iyy="5.98812e-05" iyz="2.15683e-21" izz="8.09206e-07" />
    </inertial>
    <visual>
      <origin xyz="-0.344892 -0.082765 -8.92031e-17" rpy="-1.98066 -1.5708 0" />
      <geometry>
        <mesh filename="package://assets/middle_plate_rear_axle.stl" />
      </geometry>
      <material name="middle_plate_rear_axle_material">
        <color rgba="0.768627 0.886275 0.952941 1.0" />
      </material>
    </visual>
    <collision>
      <origin xyz="-0.344892 -0.082765 -8.92031e-17" rpy="-1.98066 -1.5708 0" />
      <geometry>
        <mesh filename="package://assets/middle_plate_rear_axle.stl" />
      </geometry>
    </collision>
  </link>
  <link name="back_link_2">
    <inertial>
      <origin xyz="-0.12894 0.102954 0.0525" rpy="0 0 0" />
      <mass value="0.372616" />
      <inertia ixx="0.00174337" ixy="0.00148424" ixz="4.54738e-24" iyy="0.00241711" iyz="5.13726e-24" izz="0.00306294" />
    </inertial>
    <visual>
      <origin xyz="-0.305341 0.180465 0.0525" rpy="1.45921 1.5708 0" />
      <geometry>
        <mesh filename="package://assets/back_link.stl" />
      </geometry>
      <material name="back_link_2_material">
        <color rgba="0.231373 0.380392 0.705882 1.0" />
      </material>
    </visual>
    <collision>
      <origin xyz="-0.305341 0.180465 0.0525" rpy="1.45921 1.5708 0" />
      <geometry>
        <mesh filename="package://assets/back_link.stl" />
      </geometry>
    </collision>
  </link>
  <joint name="Cylindrical 5" type="revolute">
    <origin xyz="-4.16334e-17 0 0.0525" rpy="-3.14159 -8.54642e-17 -0.409867" />
    <parent link="middle_plate_rear_axle" />
    <child link="back_link_2" />
    <axis xyz="0 0 1" />
    <limit effort="10" velocity="10" lower="-3.141592653589793" upper="3.141592653589793" />
  </joint>
  <link name="middle_plate_2">
    <inertial>
      <origin xyz="-0.0314993 -0.0131017 0.0474999" rpy="0 0 0" />
      <mass value="0.0911859" />
      <inertia ixx="9.37918e-05" ixy="-1.12822e-05" ixz="-1.02731e-10" iyy="0.000117432" iyz="-1.57143e-10" izz="3.64426e-05" />
    </inertial>
    <visual>
      <origin xyz="-0.283345 0.213345 0.0475" rpy="1.5708 1.5708 0" />
      <geometry>
        <mesh filename="package://assets/middle_plate.stl" />
      </geometry>
      <material name="middle_plate_2_material">
        <color rgba="0.917647 0.917647 0.917647 1.0" />
      </material>
    </visual>
    <collision>
      <origin xyz="-0.283345 0.213345 0.0475" rpy="1.5708 1.5708 0" />
      <geometry>
        <mesh filename="package://assets/middle_plate.stl" />
      </geometry>
    </collision>
  </link>
  <joint name="Cylindrical 6" type="revolute">
    <origin xyz="-6.93889e-17 8.32667e-17 0.0475" rpy="-3.14159 -8.71082e-17 -0.388218" />
    <parent link="middle_plate_rear_axle" />
    <child link="middle_plate_2" />
    <axis xyz="0 0 1" />
    <limit effort="10" velocity="10" lower="-3.141592653589793" upper="3.141592653589793" />
  </joint>
  <joint name="Revolute 8" type="revolute">
    <origin xyz="0.118333 0.253766 2.46519e-32" rpy="3.14159 -0 0" />
    <parent link="top_back_link" />
    <child link="middle_plate_rear_axle" />
    <axis xyz="0 0 1" />
    <limit effort="10" velocity="10" lower="-3.141592653589793" upper="3.141592653589793" />
  </joint>
  <joint name="Revolute 3" type="revolute">
    <origin xyz="1.73472e-17 0 0" rpy="-3.14159 1.04068e-16 0.491877" />
    <parent link="top_rear_axle_2" />
    <child link="top_back_link" />
    <axis xyz="0 0 1" />
    <limit effort="10" velocity="10" lower="-3.141592653589793" upper="3.141592653589793" />
  </joint>
  <joint name="Cylindrical 2" type="revolute">
    <origin xyz="0 -0.0255 1.76291e-17" rpy="2.44517e-20 1.92716e-17 -1.56955" />
    <parent link="top_fork" />
    <child link="top_rear_axle_2" />
    <axis xyz="0 0 1" />
    <limit effort="10" velocity="10" lower="-3.141592653589793" upper="3.141592653589793" />
  </joint>
  <joint name="Revolute 2" type="revolute">
    <origin xyz="1.38778e-17 -5.55112e-17 7.85779e-32" rpy="-2.64904e-16 2.71115e-16 1.73289" />
    <parent link="top_rear_axle" />
    <child link="top_fork" />
    <axis xyz="0 0 1" />
    <limit effort="10" velocity="10" lower="-3.141592653589793" upper="3.141592653589793" />
  </joint>
  <joint name="Cylindrical 1" type="revolute">
    <origin xyz="0.0437042 -0.0249036 1.14867e-17" rpy="-3.14159 -5.72407e-16 0.00168445" />
    <parent link="top_plate" />
    <child link="top_rear_axle" />
    <axis xyz="0 0 1" />
    <limit effort="10" velocity="10" lower="-3.141592653589793" upper="3.141592653589793" />
  </joint>
  <link name="body">
    <inertial>
      <origin xyz="-2.65274e-08 0.000375995 -0.209443" rpy="0 0 0" />
      <mass value="9.21129" />
      <inertia ixx="0.128408" ixy="-7.54258e-10" ixz="-8.80985e-09" iyy="0.169216" iyz="0.000621246" izz="0.0548253" />
    </inertial>
    <visual>
      <origin xyz="-6.77502e-16 0.04 0.8" rpy="3.14159 -7.93016e-16 -6.16298e-33" />
      <geometry>
        <mesh filename="package://assets/body.stl" />
      </geometry>
      <material name="body_material">
        <color rgba="0.647059 0.647059 0.647059 1.0" />
      </material>
    </visual>
    <collision>
      <origin xyz="-6.77502e-16 0.04 0.8" rpy="3.14159 -7.93016e-16 -6.16298e-33" />
      <geometry>
        <mesh filename="package://assets/body.stl" />
      </geometry>
    </collision>
  </link>
  <link name="right_upper_arm">
    <inertial>
      <origin xyz="0 0 0" rpy="0 0 0" />
      <mass value="1e-09" />
      <inertia ixx="1e-09" ixy="0" ixz="0" iyy="1e-09" iyz="0" izz="1e-09" />
    </inertial>
    <visual>
      <origin xyz="-0.04 1.055 -0.208" rpy="1.5708 1.5708 0" />
      <geometry>
        <mesh filename="package://assets/right_upper_arm.stl" />
      </geometry>
      <material name="right_upper_arm_material">
        <color rgba="0.647059 0.647059 0.647059 1.0" />
      </material>
    </visual>
    <collision>
      <origin xyz="-0.04 1.055 -0.208" rpy="1.5708 1.5708 0" />
      <geometry>
        <mesh filename="package://assets/right_upper_arm.stl" />
      </geometry>
    </collision>
  </link>
  <link name="right_elbow_axle">
    <inertial>
      <origin xyz="0 0 0" rpy="0 0 0" />
      <mass value="1e-09" />
      <inertia ixx="1e-09" ixy="0" ixz="0" iyy="1e-09" iyz="0" izz="1e-09" />
    </inertial>
    <visual>
      <origin xyz="-0.04 0.7831 -0.2105" rpy="1.5708 1.5708 0" />
      <geometry>
        <mesh filename="package://assets/right_elbow_axle.stl" />
      </geometry>
      <material name="right_elbow_axle_material">
        <color rgba="0.615686 0.811765 0.929412 1.0" />
      </material>
    </visual>
    <collision>
      <origin xyz="-0.04 0.7831 -0.2105" rpy="1.5708 1.5708 0" />
      <geometry>
        <mesh filename="package://assets/right_elbow_axle.stl" />
      </geometry>
    </collision>
  </link>
  <link name="right_forearm">
    <inertial>
      <origin xyz="0 0 0" rpy="0 0 0" />
      <mass value="1e-09" />
      <inertia ixx="1e-09" ixy="0" ixz="0" iyy="1e-09" iyz="0" izz="1e-09" />
    </inertial>
    <visual>
      <origin xyz="-0.04 0.7831 -0.198" rpy="1.5708 1.5708 0" />
      <geometry>
        <mesh filename="package://assets/right_forearm.stl" />
      </geometry>
      <material name="right_forearm_material">
        <color rgba="0.498039 0.498039 0.498039 1.0" />
      </material>
    </visual>
    <collision>
      <origin xyz="-0.04 0.7831 -0.198" rpy="1.5708 1.5708 0" />
      <geometry>
        <mesh filename="package://assets/right_forearm.stl" />
      </geometry>
    </collision>
  </link>
  <joint name="Revolute 12" type="revolute">
    <origin xyz="3.1225e-17 2.77556e-16 -0.0125" rpy="-4.01109e-18 1.14234e-16 -2.39736" />
    <parent link="right_elbow_axle" />
    <child link="right_forearm" />
    <axis xyz="0 0 1" />
    <limit effort="10" velocity="10" lower="-3.141592653589793" upper="3.141592653589793" />
  </joint>
  <joint name="Revolute 11" type="revolute">
    <origin xyz="-1.11022e-16 0.2719 0.0025" rpy="-8.04804e-17 4.49397e-17 3.06249" />
    <parent link="right_upper_arm" />
    <child link="right_elbow_axle" />
    <axis xyz="0 0 1" />
    <limit effort="10" velocity="10" lower="-3.141592653589793" upper="3.141592653589793" />
  </joint>
  <joint name="Revolute 9" type="revolute">
    <origin xyz="-0.21 -2.77556e-17 -0.255" rpy="1.5708 -0.32657 -1.5708" />
    <parent link="body" />
    <child link="right_upper_arm" />
    <axis xyz="0 0 1" />
    <limit effort="10" velocity="10" lower="-3.141592653589793" upper="3.141592653589793" />
  </joint>
  <link name="upper_arm">
    <inertial>
      <origin xyz="0 0 0" rpy="0 0 0" />
      <mass value="1e-09" />
      <inertia ixx="1e-09" ixy="0" ixz="0" iyy="1e-09" iyz="0" izz="1e-09" />
    </inertial>
    <visual>
      <origin xyz="-0.340829 0.99923 0.208" rpy="1.27998 1.5708 0" />
      <geometry>
        <mesh filename="package://assets/upper_arm.stl" />
      </geometry>
      <material name="upper_arm_material">
        <color rgba="0.647059 0.647059 0.647059 1.0" />
      </material>
    </visual>
    <collision>
      <origin xyz="-0.340829 0.99923 0.208" rpy="1.27998 1.5708 0" />
      <geometry>
        <mesh filename="package://assets/upper_arm.stl" />
      </geometry>
    </collision>
  </link>
  <link name="left_elbow_axle">
    <inertial>
      <origin xyz="0 0 0" rpy="0 0 0" />
      <mass value="1e-09" />
      <inertia ixx="1e-09" ixy="0" ixz="0" iyy="1e-09" iyz="0" izz="1e-09" />
    </inertial>
    <visual>
      <origin xyz="-0.04 0.7831 0.1855" rpy="1.5708 1.5708 0" />
      <geometry>
        <mesh filename="package://assets/left_elbow_axle.stl" />
      </geometry>
      <material name="left_elbow_axle_material">
        <color rgba="0.615686 0.811765 0.929412 1.0" />
      </material>
    </visual>
    <collision>
      <origin xyz="-0.04 0.7831 0.1855" rpy="1.5708 1.5708 0" />
      <geometry>
        <mesh filename="package://assets/left_elbow_axle.stl" />
      </geometry>
    </collision>
  </link>
  <link name="forearm">
    <inertial>
      <origin xyz="0 0 0" rpy="0 0 0" />
      <mass value="1e-09" />
      <inertia ixx="1e-09" ixy="0" ixz="0" iyy="1e-09" iyz="0" izz="1e-09" />
    </inertial>
    <visual>
      <origin xyz="0.688301 0.375616 0.198" rpy="2.69308 1.5708 0" />
      <geometry>
        <mesh filename="package://assets/forearm.stl" />
      </geometry>
      <material name="forearm_material">
        <color rgba="0.498039 0.498039 0.498039 1.0" />
      </material>
    </visual>
    <collision>
      <origin xyz="0.688301 0.375616 0.198" rpy="2.69308 1.5708 0" />
      <geometry>
        <mesh filename="package://assets/forearm.stl" />
      </geometry>
    </collision>
  </link>
  <joint name="Revolute 14" type="revolute">
    <origin xyz="5.55112e-17 0 -0.0125" rpy="4.93038e-32 6.77927e-32 0" />
    <parent link="left_elbow_axle" />
    <child link="forearm" />
    <axis xyz="0 0 1" />
    <limit effort="10" velocity="10" lower="-3.141592653589793" upper="3.141592653589793" />
  </joint>
  <joint name="Revolute 13" type="revolute">
    <origin xyz="-0.0779642 0.260483 0.0225" rpy="-1.63547e-16 -6.95894e-17 1.99722" />
    <parent link="upper_arm" />
    <child link="left_elbow_axle" />
    <axis xyz="0 0 1" />
    <limit effort="10" velocity="10" lower="-3.141592653589793" upper="3.141592653589793" />
  </joint>
  <joint name="Revolute 10" type="revolute">
    <origin xyz="0.21 0 -0.255" rpy="1.5708 -0 -1.5708" />
    <parent link="body" />
    <child link="upper_arm" />
    <axis xyz="0 0 1" />
    <limit effort="10" velocity="10" lower="-3.141592653589793" upper="3.141592653589793" />
  </joint>
  <joint name="Fastened 2" type="fixed">
    <origin xyz="-0.000750282 -0.0269154 -4.83738e-16" rpy="-1.16242 1.5708 0" />
    <parent link="top_plate" />
    <child link="body" />
    <axis xyz="0 0 1" />
    <limit effort="10" velocity="10" />
  </joint>
  <joint name="Revolute 1" type="revolute">
    <origin xyz="8.32667e-17 -3.33067e-16 0.045" rpy="3.14159 -1.17916e-15 -0.790723" />
    <parent link="top_front_axle" />
    <child link="top_plate" />
    <axis xyz="0 0 1" />
    <limit effort="10" velocity="10" lower="-3.141592653589793" upper="3.141592653589793" />
  </joint>
  <link name="top_left_link_2">
    <inertial>
      <origin xyz="0.0591666 -0.126883 -0.005" rpy="0 0 0" />
      <mass value="0.1376" />
      <inertia ixx="0.000774541" ixy="0.0003589" ixz="-1.42146e-35" iyy="0.000172235" iyz="-3.13635e-35" izz="0.000944753" />
    </inertial>
    <visual>
      <origin xyz="-0.115012 -0.487111 -0.055" rpy="-1.5708 -1.5708 0" />
      <geometry>
        <mesh filename="package://assets/top_left_link.stl" />
      </geometry>
      <material name="top_left_link_2_material">
        <color rgba="0.498039 0.498039 0.498039 1.0" />
      </material>
    </visual>
    <collision>
      <origin xyz="-0.115012 -0.487111 -0.055" rpy="-1.5708 -1.5708 0" />
      <geometry>
        <mesh filename="package://assets/top_left_link.stl" />
      </geometry>
    </collision>
  </link>
  <joint name="Cylindrical 3" type="revolute">
    <origin xyz="0 -2.22045e-16 0.1" rpy="-8.58656e-16 -8.02604e-16 -7.77156e-16" />
    <parent link="top_front_axle" />
    <child link="top_left_link_2" />
    <axis xyz="0 0 1" />
    <limit effort="10" velocity="10" lower="-3.141592653589793" upper="3.141592653589793" />
  </joint>
  <joint name="Cylindrical 4" type="revolute">
    <origin xyz="-0.118333 -0.253766 0" rpy="3.14159 -0 0" />
    <parent link="top_right_link" />
    <child link="top_front_axle" />
    <axis xyz="0 0 1" />
    <limit effort="10" velocity="10" lower="-3.141592653589793" upper="3.141592653589793" />
  </joint>
  <joint name="Cylindrical 12" type="revolute">
    <origin xyz="4.85723e-17 -5.55112e-17 0.045" rpy="1.71797e-22 2.0413e-21 -0.609978" />
    <parent link="middle_plate_front_axle" />
    <child link="top_right_link" />
    <axis xyz="0 0 1" />
    <limit effort="10" velocity="10" lower="-3.141592653589793" upper="3.141592653589793" />
  </joint>
  <joint name="Revolute 4" type="revolute">
    <origin xyz="0.257126 0.206849 -3.45606e-16" rpy="3.14159 9.09154e-16 -0.0530963" />
    <parent link="front_bottom_link" />
    <child link="middle_plate_front_axle" />
    <axis xyz="0 0 1" />
    <limit effort="10" velocity="10" lower="-3.141592653589793" upper="3.141592653589793" />
  </joint>
  <joint name="Revolute 5" type="revolute">
    <origin xyz="2.08167e-19 6.93889e-18 -0.02" rpy="3.58771e-46 2.81666e-31 2.77209e-15" />
    <parent link="front_axle_joint" />
    <child link="front_bottom_link" />
    <axis xyz="0 0 1" />
    <limit effort="10" velocity="10" lower="-3.141592653589793" upper="3.141592653589793" />
  </joint>
  <joint name="Cylindrical 11" type="revolute">
    <origin xyz="0.02 -2.08167e-19 -0.0175" rpy="-1.5708 -0 -1.5708" />
    <parent link="front_joint_fork" />
    <child link="front_axle_joint" />
    <axis xyz="0 0 1" />
    <limit effort="10" velocity="10" lower="-3.141592653589793" upper="3.141592653589793" />
  </joint>
  <joint name="Fastened 4" type="fixed">
    <origin xyz="-0.04 -0.0518864 0.02" rpy="3.14159 -0 0" />
    <parent link="base" />
    <child link="front_joint_fork" />
    <axis xyz="0 0 1" />
    <limit effort="10" velocity="10" />
  </joint>
  <link name="back_right_base_fork">
    <inertial>
      <origin xyz="2.08167e-17 0 -0.00666159" rpy="0 0 0" />
      <mass value="0.0418822" />
      <inertia ixx="2.42204e-06" ixy="0" ixz="5.19147e-70" iyy="1.00185e-05" iyz="0" izz="9.25611e-06" />
    </inertial>
    <visual>
      <origin xyz="0.04 0.05 -0.0375" rpy="3.14159 7.59645e-65 0" />
      <geometry>
        <mesh filename="package://assets/back_right_base_fork.stl" />
      </geometry>
      <material name="back_right_base_fork_material">
        <color rgba="0.647059 0.647059 0.647059 1.0" />
      </material>
    </visual>
    <collision>
      <origin xyz="0.04 0.05 -0.0375" rpy="3.14159 7.59645e-65 0" />
      <geometry>
        <mesh filename="package://assets/back_right_base_fork.stl" />
      </geometry>
    </collision>
  </link>
  <link name="back_right_axle">
    <inertial>
      <origin xyz="-3.40711e-17 6.93889e-18 0.015" rpy="0 0 0" />
      <mass value="0.0246615" />
      <inertia ixx="3.44233e-06" ixy="-7.00843e-25" ixz="-2.07617e-37" iyy="3.44233e-06" iyz="2.10992e-39" izz="3.08269e-07" />
    </inertial>
    <visual>
      <origin xyz="-0.0501145 0.0197114 0.055" rpy="-1.56503 -1.5708 0" />
      <geometry>
        <mesh filename="package://assets/back_right_axle.stl" />
      </geometry>
      <material name="back_right_axle_material">
        <color rgba="0.615686 0.811765 0.929412 1.0" />
      </material>
    </visual>
    <collision>
      <origin xyz="-0.0501145 0.0197114 0.055" rpy="-1.56503 -1.5708 0" />
      <geometry>
        <mesh filename="package://assets/back_right_axle.stl" />
      </geometry>
    </collision>
  </link>
  <link name="back_link_3">
    <inertial>
      <origin xyz="0.128521 0.103477 0.04" rpy="0 0 0" />
      <mass value="0.372616" />
      <inertia ixx="0.00175543" ixy="-0.00148693" ixz="-4.59599e-24" iyy="0.00240505" iyz="5.14241e-24" izz="0.00306294" />
    </inertial>
    <visual>
      <origin xyz="-0.0475647 0.0252508 0.04" rpy="-1.67833 -1.5708 0" />
      <geometry>
        <mesh filename="package://assets/back_link.stl" />
      </geometry>
      <material name="back_link_3_material">
        <color rgba="0.231373 0.380392 0.705882 1.0" />
      </material>
    </visual>
    <collision>
      <origin xyz="-0.0475647 0.0252508 0.04" rpy="-1.67833 -1.5708 0" />
      <geometry>
        <mesh filename="package://assets/back_link.stl" />
      </geometry>
    </collision>
  </link>
  <joint name="Revolute 7" type="revolute">
    <origin xyz="-3.48332e-17 6.93889e-18 0.015" rpy="8.52776e-34 4.15976e-32 0.00576548" />
    <parent link="back_right_axle" />
    <child link="back_link_3" />
    <axis xyz="0 0 1" />
    <limit effort="10" velocity="10" lower="-3.141592653589793" upper="3.141592653589793" />
  </joint>
  <joint name="Cylindrical 9" type="revolute">
    <origin xyz="-0.015 1.38778e-19 -0.0175" rpy="-1.5708 -0 -1.5708" />
    <parent link="back_right_base_fork" />
    <child link="back_right_axle" />
    <axis xyz="0 0 1" />
    <limit effort="10" velocity="10" lower="-3.141592653589793" upper="3.141592653589793" />
  </joint>
  <joint name="Fastened 6" type="fixed">
    <origin xyz="-0.08 -1.37997e-17 -6.93889e-18" rpy="3.14159 4.27642e-50 1.2326e-32" />
    <parent link="base" />
    <child link="back_right_base_fork" />
    <axis xyz="0 0 1" />
    <limit effort="10" velocity="10" />
  </joint>
  <joint name="Fastened 5" type="fixed">
    <origin xyz="7.80626e-20 0.0175 0.02" rpy="1.5708 1.5708 0" />
    <parent link="back_left_base_fork" />
    <child link="base" />
    <axis xyz="0 0 1" />
    <limit effort="10" velocity="10" />
  </joint>
  <joint name="Cylindrical 10" type="revolute">
    <origin xyz="0.06 -0.0492115 0.04" rpy="-1.5708 -3.46945e-18 1.5708" />
    <parent link="back_left_axle" />
    <child link="back_left_base_fork" />
    <axis xyz="0 0 1" />
    <limit effort="10" velocity="10" lower="-3.141592653589793" upper="3.141592653589793" />
  </joint>
</robot>
